Workbook

Sheet Dashboard
A1: SOR/SCIP Static Dataset Update
A2: Updated on | B2: 2026-06-09 16:45
A3: Change made | B3: Deleted Alexianer GmbH; inserted Hochschule für Musik Mainz and Hochschule für Gesellschaftsgestaltung (HfGG).
A4: Members in universe M | B4: 102
A5: Concrete clusters K | B5: 24
A6: Candidate cards P | B6: 694
A7: SCIP model | B7: Binary weighted set-packing over Excel-defined candidate universe P.
A8: Objective | B8: maximize SUM(final_support_score_p * selected_x_p)
A9: Candidate generation | B9: For each cluster, pair members with relevance >=3; score and rank; keep top 30 per cluster.
A10: Scoring | B10: Static score = positive support components minus penalties. Live crawler/feedback can later add dynamic boosts.
A12: Update | B12: Static ZIRP info-box keyword radar added
A13: New sheet | B13: InfoBox_Keyword_Radar
A14: Members covered | B14: 103
A15: Dictionary | B15: Keyword_Dictionary
A16: Summary | B16: Keyword_Summary
A18: Update | B18: Role-weighted SCIP constraint layer added
A19: New sheets | B19: Role_Weights; Member_Role_Weights; Candidate_Role_Balance; SCIP_Role_Constraint_Readme
A20: Logic | B20: Each role gets total mass 1 via 1 / count(role). Candidate pair mass = weight(role_a)+weight(role_b).
A21: Use | B21: Use role_balanced_score as objective input and role exposure as SCIP audit/constraint.
A22: Created | B22: 2026-06-13

Sheet All_ZIRP_Members
A1: member_id | B1: member_name | C1: homepage | D1: actor_role | E1: actor_subrole | F1: cluster_count | G1: max_cluster_relevance | H1: broad_zirp_fields | I1: top_static_clusters
A2: 1 | B2: 1. FSV Mainz 05 e.V. | C2: https://www.mainz05.de | D2: context_actor | E2: sports_regional_identity_anchor | F2: 4 | G2: 5 | H2: gesellschaft, kultur | I2: Sport, Region und gesellschaftliche Identifikation (5); Kultur, Standortidentität und regionale Attraktivität (4); Demokratie, Medien und gesellschaftlicher Zusammenhalt (3); Kreativwirtschaft, Medien und digitale Öffentlichkeit (3)
A3: 2 | B3: AOK Rheinland-Pfalz/Saarland | C3: https://www.aok.de/rheinland-pfalz | D3: context_actor | E3: health_social_anchor | F3: 3 | G3: 5 | H3: gesellschaft | I3: Gesundheitsversorgung und Prävention (5); Pflege, Fachkräfte und Sozialwirtschaft (4); Sport, Region und gesellschaftliche Identifikation (4)
A4: 3 | B4: Architektenkammer Rheinland-Pfalz | C4: https://www.diearchitekten.org | D4: implementation_anchor | E4: construction_planning_anchor | F4: 3 | G4: 5 | H4: nachhaltigkeit, technologie | I4: Digitale Bau-, Planungs- und Genehmigungsprozesse (5); Klimaanpassung in Stadt und Land (4); Kreislaufwirtschaft, Bau und Ersatzbaustoffverordnung (4)
A5: 4 | B5: Aturas GmbH | C5: https://aturas.com | D5: profit_anchor | E5: technology_digital_anchor | F5: 4 | G5: 4 | H5: technologie, wirtschaft, wissen | I5: Digitale Bau-, Planungs- und Genehmigungsprozesse (4); KI, Daten und Verwaltungs-/Wirtschaftsanwendungen (4); Mittelstand, Digitalisierung und Produktivität (4); Verwaltungswissen und digitale Umsetzung (4)
A6: 5 | B6: Barmherzige Brüder Trier gGmbH | C6: https://www.bbtgruppe.de | D6: context_actor | E6: health_social_anchor | F6: 5 | G6: 5 | H6: gesellschaft, wirtschaft, wissen | I6: Pflege, Fachkräfte und Sozialwirtschaft (5); Arbeitsmarkt, Fachkräfte und Qualifizierung (4); Gesundheitsversorgung und Prävention (4); Teilhabe, Inklusion und Arbeitsmarkt (4); Weiterbildung und lebenslanges Lernen (4)
A7: 6 | B7: BASF SE | C7: https://www.basf.com | D7: profit_anchor | E7: industry_anchor | F7: 5 | G7: 5 | H7: nachhaltigkeit, technologie, wirtschaft, wissen | I7: Standort, Investition und industrielle Transformation (5); Energie, Netze und Versorgungssicherheit (4); Hochschule-Wirtschaft-Transfer (4); Industrie 4.0, Automatisierung und Produktion (4); Arbeitsmarkt, Fachkräfte und Qualifizierung (3)
A8: 7 | B8: Bauern- und Winzerverband Rheinland-Pfalz Süd e.V. | C8: https://www.bwv-rlp.de | D8: implementation_anchor | E8: agriculture_wine_anchor | F8: 1 | G8: 5 | H8: nachhaltigkeit | I8: Klimaanpassung in Stadt und Land (5)
A9: 8 | B9: Bauwirtschaft Rheinland-Pfalz e.V. | C9: https://www.bauwirtschaft-rlp.de | D9: context_actor | E9: construction_planning_anchor | F9: 3 | G9: 5 | H9: nachhaltigkeit, technologie | I9: Digitale Bau-, Planungs- und Genehmigungsprozesse (5); Kreislaufwirtschaft, Bau und Ersatzbaustoffverordnung (5); Klimaanpassung in Stadt und Land (4)
A10: 9 | B10: Bernd Hummel Holding GmbH | C10: https://www.bernd-hummel.de | D10: profit_anchor | E10: industry_anchor | F10: 0 | G10: 0
A11: 10 | B11: Bitburger Braugruppe GmbH | C11: https://www.bitburger-braugruppe.de | D11: profit_anchor | E11: food_beverage_consumer_anchor | F11: 1 | G11: 4 | H11: wirtschaft | I11: Standort, Investition und industrielle Transformation (4)
A12: 11 | B12: Boehringer Ingelheim Pharma GmbH & Co. KG | C12: https://www.boehringer-ingelheim.com/de | D12: profit_anchor | E12: health_social_anchor | F12: 5 | G12: 5 | H12: gesellschaft, wirtschaft, wissen | I12: Standort, Investition und industrielle Transformation (5); Gesundheitsversorgung und Prävention (4); Hochschule-Wirtschaft-Transfer (4); Arbeitsmarkt, Fachkräfte und Qualifizierung (3); Finanzierung und Förderung von Transformation (3)
A13: 12 | B13: BRICKMAKERS AG | C13: http://www.brickmakers.de | D13: profit_anchor | E13: technology_digital_anchor | F13: 5 | G13: 5 | H13: technologie, wirtschaft, wissen | I13: KI, Daten und Verwaltungs-/Wirtschaftsanwendungen (5); Mittelstand, Digitalisierung und Produktivität (5); Cyberresilienz und kritische Infrastruktur (4); Digitale Bau-, Planungs- und Genehmigungsprozesse (4); Hochschule-Wirtschaft-Transfer (4)
A14: 13 | B14: Bundesagentur für Arbeit, Regionaldirektion Rheinland-Pfalz-Saarland | C14: https://www.arbeitsagentur.de | D14: implementation_anchor | E14: public_policy_anchor | F14: 4 | G14: 5 | H14: gesellschaft, wirtschaft, wissen | I14: Arbeitsmarkt, Fachkräfte und Qualifizierung (5); Pflege, Fachkräfte und Sozialwirtschaft (5); Teilhabe, Inklusion und Arbeitsmarkt (5); Weiterbildung und lebenslanges Lernen (5)
A15: 14 | B15: Caritasverband für die Diözese Speyer e.V. | C15: https://www.caritas-speyer.de | D15: implementation_anchor | E15: health_social_anchor | F15: 5 | G15: 5 | H15: gesellschaft, wirtschaft | I15: Pflege, Fachkräfte und Sozialwirtschaft (5); Teilhabe, Inklusion und Arbeitsmarkt (5); Arbeitsmarkt, Fachkräfte und Qualifizierung (4); Demokratie, Medien und gesellschaftlicher Zusammenhalt (4); Gesundheitsversorgung und Prävention (4)
A16: 15 | B16: Continental Automotive Technologies GmbH, Safety and Motion (SAM), Standort Rheinböllen | C16: https://www.continental-corporation.de | D16: profit_anchor | E16: industry_anchor | F16: 2 | G16: 5 | H16: technologie, wirtschaft | I16: Industrie 4.0, Automatisierung und Produktion (5); Standort, Investition und industrielle Transformation (4)
A17: 16 | B17: Debeka Versicherungsgruppe | C17: https://www.debeka.de | D17: profit_anchor | E17: bank_finance_anchor | F17: 3 | G17: 4 | H17: technologie, wirtschaft | I17: Cyberresilienz und kritische Infrastruktur (4); Finanzierung und Förderung von Transformation (4); Standort, Investition und industrielle Transformation (4)
A18: 17 | B18: Deutsche Bundesbank, Hauptverwaltung in Rheinland-Pfalz und dem Saarland | C18: https://www.bundesbank.de | D18: context_actor | E18: bank_finance_anchor | F18: 1 | G18: 4 | H18: technologie | I18: Cyberresilienz und kritische Infrastruktur (4)
A19: 18 | B19: Deutsche Telekom AG | C19: https://www.telekom.de | D19: profit_anchor | E19: technology_digital_anchor | F19: 5 | G19: 5 | H19: kultur, technologie, wirtschaft | I19: Cyberresilienz und kritische Infrastruktur (5); KI, Daten und Verwaltungs-/Wirtschaftsanwendungen (5); Mittelstand, Digitalisierung und Produktivität (5); Industrie 4.0, Automatisierung und Produktion (4); Kreativwirtschaft, Medien und digitale Öffentlichkeit (4)
A20: 19 | B20: Deutsche Universität für Verwaltungswissenschaften Speyer | C20: https://www.uni-speyer.de | D20: academic_support | E20: university_research | F20: 5 | G20: 5 | H20: gesellschaft, technologie, wissen | I20: Demokratie, Medien und gesellschaftlicher Zusammenhalt (5); KI, Daten und Verwaltungs-/Wirtschaftsanwendungen (5); Verwaltungswissen und digitale Umsetzung (5); Wissenschaft, Demokratie und gesellschaftlicher Zusammenhalt (5); Digitale Bau-, Planungs- und Genehmigungsprozesse (4)
A21: 20 | B21: Deutscher Gewerkschaftsbund (DGB) Rheinland-Pfalz/Saarland | C21: https://rlp-saarland.dgb.de | D21: context_actor | E21: chamber_association_anchor | F21: 4 | G21: 5 | H21: gesellschaft, wirtschaft, wissen | I21: Arbeitsmarkt, Fachkräfte und Qualifizierung (5); Pflege, Fachkräfte und Sozialwirtschaft (4); Teilhabe, Inklusion und Arbeitsmarkt (4); Weiterbildung und lebenslanges Lernen (4)
A22: 21 | B22: Duale Hochschule Rheinland-Pfalz | C22: https://www.dh-rlp.de | D22: academic_support | E22: university_applied_sciences | F22: 4 | G22: 5 | H22: gesellschaft, wirtschaft, wissen | I22: Arbeitsmarkt, Fachkräfte und Qualifizierung (5); Weiterbildung und lebenslanges Lernen (5); Hochschule-Wirtschaft-Transfer (4); Pflege, Fachkräfte und Sozialwirtschaft (4)
... A29: 28 | B29: Evangelische Kirche der Pfalz | C29: https://www.evkirchepfalz.de | D29: context_actor | E29: culture_foundation_anchor | F29: 5 | G29: 5 | H29: gesellschaft, kultur, wissen | I29: Demokratie, Medien und gesellschaftlicher Zusammenhalt (5); Wissenschaft, Demokratie und gesellschaftlicher Zusammenhalt (5); Kultur, Standortidentität und regionale Attraktivität (4); Teilhabe, Inklusion und Arbeitsmarkt (4); Talentförderung, Musik und Nachwuchs (3)
A30: 29 | B30: Fachingen Heil- und Mineralbrunnen GmbH | C30: https://www.fachingen.de | D30: profit_anchor | E30: food_beverage_consumer_anchor | F30: 0 | G30: 0
A31: 30 | B31: Gerolsteiner Brunnen GmbH & Co. KG | C31: https://www.gerolsteiner.de | D31: profit_anchor | E31: food_beverage_consumer_anchor | F31: 0 | G31: 0
A32: 31 | B32: GLOBUS Markthallen Holding GmbH & Co. KG | C32: https://www.globus.de | D32: profit_anchor | E32: food_beverage_consumer_anchor | F32: 5 | G32: 4 | H32: gesellschaft, wirtschaft, wissen | I32: Standort, Investition und industrielle Transformation (4); Arbeitsmarkt, Fachkräfte und Qualifizierung (3); Sport, Region und gesellschaftliche Identifikation (3); Teilhabe, Inklusion und Arbeitsmarkt (3); Weiterbildung und lebenslanges Lernen (3)
A33: 32 | B33: Handwerkskammern Rheinland-Pfalz | C33: https://handwerk-rlp.de | D33: implementation_anchor | E33: chamber_association_anchor | F33: 5 | G33: 5 | H33: wirtschaft, wissen | I33: Arbeitsmarkt, Fachkräfte und Qualifizierung (5); Weiterbildung und lebenslanges Lernen (5); Hochschule-Wirtschaft-Transfer (4); Mittelstand, Digitalisierung und Produktivität (4); Finanzierung und Förderung von Transformation (3)
A34: 33 | B34: Heberger Gruppe | C34: https://www.heberger.de | D34: context_actor | E34: construction_planning_anchor | F34: 2 | G34: 4 | H34: nachhaltigkeit, technologie | I34: Kreislaufwirtschaft, Bau und Ersatzbaustoffverordnung (4); Digitale Bau-, Planungs- und Genehmigungsprozesse (3)
A35: 34 | B35: Hochschule für Gesellschaftsgestaltung (HfGG) | C35: https://www.hfgg.de/ | D35: academic_support | E35: university_applied_sciences | F35: 6 | G35: 5 | H35: gesellschaft, nachhaltigkeit, wissen | I35: Wissenschaft, Demokratie und gesellschaftlicher Zusammenhalt (5); Demokratie, Medien und gesellschaftlicher Zusammenhalt (4); Teilhabe, Inklusion und Arbeitsmarkt (4); Klimaanpassung in Stadt und Land (4); Hochschule-Wirtschaft-Transfer (3); Weiterbildung und lebenslanges Lernen (3)
A36: 35 | B36: Hochschule für Musik Mainz | C36: https://www.musik.uni-mainz.de/ | D36: academic_support | E36: university_applied_sciences | F36: 5 | G36: 5 | H36: kultur, wissen | I36: Talentförderung, Musik und Nachwuchs (5); Kultur, Standortidentität und regionale Attraktivität (4); Kreativwirtschaft, Medien und digitale Öffentlichkeit (3); Wissenschaft, Demokratie und gesellschaftlicher Zusammenhalt (3); Weiterbildung und lebenslanges Lernen (3)
A37: 36 | B37: Hochschule für Wirtschaft und Gesellschaft Ludwigshafen | C37: https://www.hwg-lu.de | D37: academic_support | E37: university_applied_sciences | F37: 4 | G37: 4 | H37: gesellschaft, wirtschaft, wissen | I37: Arbeitsmarkt, Fachkräfte und Qualifizierung (4); Hochschule-Wirtschaft-Transfer (4); Weiterbildung und lebenslanges Lernen (4); Gesundheitsversorgung und Prävention (3)
A38: 37 | B38: Hochschule Kaiserslautern | C38: https://www.hs-kl.de | D38: academic_support | E38: university_applied_sciences | F38: 5 | G38: 4 | H38: technologie, wirtschaft, wissen | I38: Arbeitsmarkt, Fachkräfte und Qualifizierung (4); Hochschule-Wirtschaft-Transfer (4); Industrie 4.0, Automatisierung und Produktion (4); KI, Daten und Verwaltungs-/Wirtschaftsanwendungen (4); Mittelstand, Digitalisierung und Produktivität (4)
A39: 38 | B39: Hochschule Koblenz | C39: https://www.hs-koblenz.de | D39: academic_support | E39: university_applied_sciences | F39: 5 | G39: 4 | H39: technologie, wirtschaft, wissen | I39: Arbeitsmarkt, Fachkräfte und Qualifizierung (4); Hochschule-Wirtschaft-Transfer (4); Weiterbildung und lebenslanges Lernen (4); KI, Daten und Verwaltungs-/Wirtschaftsanwendungen (3); Mittelstand, Digitalisierung und Produktivität (3)
A40: 39 | B40: Hochschule Mainz | C40: https://www.hs-mainz.de | D40: academic_support | E40: university_applied_sciences | F40: 5 | G40: 5 | H40: kultur, technologie, wirtschaft, wissen | I40: Digitale Bau-, Planungs- und Genehmigungsprozesse (5); Kreativwirtschaft, Medien und digitale Öffentlichkeit (5); Arbeitsmarkt, Fachkräfte und Qualifizierung (4); Hochschule-Wirtschaft-Transfer (4); KI, Daten und Verwaltungs-/Wirtschaftsanwendungen (4)
A41: 40 | B41: Hochschule Trier | C41: https://www.hochschule-trier.de | D41: academic_support | E41: university_applied_sciences | F41: 5 | G41: 4 | H41: nachhaltigkeit, technologie, wirtschaft, wissen | I41: Arbeitsmarkt, Fachkräfte und Qualifizierung (4); Hochschule-Wirtschaft-Transfer (4); Wasser, Umwelttechnik und kommunale Resilienz (4); Weiterbildung und lebenslanges Lernen (4); Industrie 4.0, Automatisierung und Produktion (3)
A42: 41 | B42: Hochschule Worms | C42: https://www.hs-worms.de | D42: academic_support | E42: university_applied_sciences | F42: 3 | G42: 4 | H42: wirtschaft, wissen | I42: Arbeitsmarkt, Fachkräfte und Qualifizierung (4); Hochschule-Wirtschaft-Transfer (4); Weiterbildung und lebenslanges Lernen (4)
A43: 42 | B43: IKK Südwest | C43: https://www.ikk-suedwest.de | D43: context_actor | E43: health_social_anchor | F43: 3 | G43: 5 | H43: gesellschaft | I43: Gesundheitsversorgung und Prävention (5); Pflege, Fachkräfte und Sozialwirtschaft (4); Sport, Region und gesellschaftliche Identifikation (4)
... A59: 58 | B59: KÜBLER GmbH | C59: https://www.kuebler-hallenheizungen.de | D59: profit_anchor | E59: energy_infrastructure_anchor | F59: 3 | G59: 4 | H59: nachhaltigkeit, technologie, wirtschaft | I59: Energie, Netze und Versorgungssicherheit (4); Industrie 4.0, Automatisierung und Produktion (3); Mittelstand, Digitalisierung und Produktivität (3)
A60: 59 | B60: L Q M Marktforschung GmbH | D60: profit_anchor | E60: professional_services_anchor | F60: 0 | G60: 0
A61: 60 | B61: Landesbank Baden-Württemberg (LBBW) | C61: https://www.lbbw.de | D61: profit_anchor | E61: bank_finance_anchor | F61: 4 | G61: 5 | H61: nachhaltigkeit, technologie, wirtschaft | I61: Finanzierung und Förderung von Transformation (5); Standort, Investition und industrielle Transformation (5); Cyberresilienz und kritische Infrastruktur (4); Energie, Netze und Versorgungssicherheit (3)
...

Sheet Candidate_Patterns
A1: candidate_id | B1: scip_variable | C1: selected_x | D1: member_a | E1: member_b | F1: member_a_id | G1: member_b_id | H1: role_a | I1: subrole_a | J1: role_b | K1: subrole_b | L1: themenfeld | M1: concrete_cluster | N1: cluster_label | O1: relevance_a | P1: relevance_b | Q1: shared_concrete_clusters | R1: complementary_topic_pairs | S1: momentum_from_event_count | T1: avg_decision_quality | U1: section_diversity | V1: role_complementarity | W1: application_capability_bridge | X1: broad_media_penalty | Y1: weak_profile_penalty | Z1: academic_only_penalty | AA1: abstract_overlap_penalty | AB1: final_support_score | AC1: static_cluster_problem | AD1: reasoning | AE1: member_pair_key | AF1: opportunity_key
A2: C0001 | B2: x_0001 | C2: 0 | D2: Architektenkammer Rheinland-Pfalz | E2: vero – Verband der Bau- und Rohstoffindustrie | F2: 3 | G2: 95 | H2: implementation_anchor | I2: construction_planning_anchor | J2: profit_anchor | K2: construction_planning_anchor | L2: technologie | M2: digitale_bau_verwaltung_planung | N2: Digitale Bau-, Planungs- und Genehmigungsprozesse | O2: 5 | P2: 5 | Q2: 14 | R2: 4 | S2: 0 | T2: 0 | U2: 2 | V2: 8 | W2: 8 | X2: 0 | Y2: 0 | Z2: 0 | AA2: 0 | AB2: 40.208485 | AC2: Wie können Bau, Planung, Genehmigung und Verwaltung durch digitale Werkzeuge schneller und rechtssicherer werden? | AD2: Digitale Bau-, Planungs- und Genehmigungsprozesse: Architektenkammer Rheinland-Pfalz (implementation_anchor, 5) + vero – Verband der Bau- und Rohstoffindustrie (profit_anchor, 5). | AE2: Architektenkammer Rheinland-Pfalz | vero – Verband der Bau- und Rohstoffindustrie | AF2: digitale-bau-verwaltung-planung-architektenkammer-rheinland-pfalz-vero-verband-der-bau-und-rohs
A3: C0002 | B3: x_0002 | C3: 0 | D3: Ingenieurkammer Rheinland-Pfalz | E3: vero – Verband der Bau- und Rohstoffindustrie | F3: 44 | G3: 95 | H3: implementation_anchor | I3: construction_planning_anchor | J3: profit_anchor | K3: construction_planning_anchor | L3: technologie | M3: digitale_bau_verwaltung_planung | N3: Digitale Bau-, Planungs- und Genehmigungsprozesse | O3: 5 | P3: 5 | Q3: 14 | R3: 4 | S3: 0 | T3: 0 | U3: 2 | V3: 8 | W3: 8 | X3: 0 | Y3: 0 | Z3: 0 | AA3: 0 | AB3: 40.208485 | AC3: Wie können Bau, Planung, Genehmigung und Verwaltung durch digitale Werkzeuge schneller und rechtssicherer werden? | AD3: Digitale Bau-, Planungs- und Genehmigungsprozesse: Ingenieurkammer Rheinland-Pfalz (implementation_anchor, 5) + vero – Verband der Bau- und Rohstoffindustrie (profit_anchor, 5). | AE3: Ingenieurkammer Rheinland-Pfalz | vero – Verband der Bau- und Rohstoffindustrie | AF3: digitale-bau-verwaltung-planung-ingenieurkammer-rheinland-pfalz-vero-verband-der-bau-und-rohsto
A4: C0003 | B4: x_0003 | C4: 0 | D4: Bundesagentur für Arbeit, Regionaldirektion Rheinland-Pfalz-Saarland | E4: Leonardo PersonalKonzept GmbH | F4: 13 | G4: 64 | H4: implementation_anchor | I4: public_policy_anchor | J4: profit_anchor | K4: professional_services_anchor | L4: wirtschaft | M4: arbeitsmarkt_fachkraefte | N4: Arbeitsmarkt, Fachkräfte und Qualifizierung | O4: 5 | P4: 4 | Q4: 13 | R4: 4 | S4: 0 | T4: 0 | U4: 2 | V4: 8 | W4: 8 | X4: 0 | Y4: 0 | Z4: 0 | AA4: 0 | AB4: 47.342258 | AC4: Wie sichern Unternehmen, Hochschulen, Kammern und Arbeitsverwaltung Fachkräfte für Transformation, Pflege, Technik und Verwaltung? | AD4: Arbeitsmarkt, Fachkräfte und Qualifizierung: Bundesagentur für Arbeit, Regionaldirektion Rheinland-Pfalz-Saarland (implementation_anchor, 5) + Leonardo PersonalKonzept GmbH (profit_anchor, 4). | AE4: Bundesagentur für Arbeit, Regionaldirektion Rheinland-Pfalz-Saarland | Leonardo PersonalKonzept GmbH | AF4: arbeitsmarkt-fachkraefte-bundesagentur-für-arbeit-regionaldirektion-rheinland-pfalz-saarland-le
A5: C0004 | B5: x_0004 | C5: 0 | D5: Bundesagentur für Arbeit, Regionaldirektion Rheinland-Pfalz-Saarland | E5: Ministerium für Wirtschaft, Verkehr, Landwirtschaft und Weinbau | F5: 13 | G5: 70 | H5: implementation_anchor | I5: public_policy_anchor | J5: profit_anchor | K5: public_policy_anchor | L5: wirtschaft | M5: arbeitsmarkt_fachkraefte | N5: Arbeitsmarkt, Fachkräfte und Qualifizierung | O5: 5 | P5: 4 | Q5: 13 | R5: 4 | S5: 0 | T5: 0 | U5: 2 | V5: 8 | W5: 8 | X5: 0 | Y5: 0 | Z5: 0 | AA5: 0 | AB5: 45.139072 | AC5: Wie sichern Unternehmen, Hochschulen, Kammern und Arbeitsverwaltung Fachkräfte für Transformation, Pflege, Technik und Verwaltung? | AD5: Arbeitsmarkt, Fachkräfte und Qualifizierung: Bundesagentur für Arbeit, Regionaldirektion Rheinland-Pfalz-Saarland (implementation_anchor, 5) + Ministerium für Wirtschaft, Verkehr, Landwirtschaft und Weinbau (profit_anchor, 4). | AE5: Bundesagentur für Arbeit, Regionaldirektion Rheinland-Pfalz-Saarland | Ministerium für Wirtschaft, Verkehr, Landwirtschaft und Weinbau | AF5: arbeitsmarkt-fachkraefte-bundesagentur-für-arbeit-regionaldirektion-rheinland-pfalz-saarland-mi
A6: C0005 | B6: x_0005 | C6: 0 | D6: Handwerkskammern Rheinland-Pfalz | E6: Leonardo PersonalKonzept GmbH | F6: 32 | G6: 64 | H6: implementation_anchor | I6: chamber_association_anchor | J6: profit_anchor | K6: professional_services_anchor | L6: wirtschaft | M6: arbeitsmarkt_fachkraefte | N6: Arbeitsmarkt, Fachkräfte und Qualifizierung | O6: 5 | P6: 4 | Q6: 13 | R6: 4 | S6: 0 | T6: 0 | U6: 2 | V6: 8 | W6: 8 | X6: 0 | Y6: 0 | Z6: 0 | AA6: 0 | AB6: 52.446862 | AC6: Wie sichern Unternehmen, Hochschulen, Kammern und Arbeitsverwaltung Fachkräfte für Transformation, Pflege, Technik und Verwaltung? | AD6: Arbeitsmarkt, Fachkräfte und Qualifizierung: Handwerkskammern Rheinland-Pfalz (implementation_anchor, 5) + Leonardo PersonalKonzept GmbH (profit_anchor, 4). | AE6: Handwerkskammern Rheinland-Pfalz | Leonardo PersonalKonzept GmbH | AF6: arbeitsmarkt-fachkraefte-handwerkskammern-rheinland-pfalz-leonardo-personalkonzept-gmbh
A7: C0006 | B7: x_0006 | C7: 0 | D7: Handwerkskammern Rheinland-Pfalz | E7: Ministerium für Wirtschaft, Verkehr, Landwirtschaft und Weinbau | F7: 32 | G7: 70 | H7: implementation_anchor | I7: chamber_association_anchor | J7: profit_anchor | K7: public_policy_anchor | L7: wirtschaft | M7: arbeitsmarkt_fachkraefte | N7: Arbeitsmarkt, Fachkräfte und Qualifizierung | O7: 5 | P7: 4 | Q7: 13 | R7: 4 | S7: 0 | T7: 0 | U7: 2 | V7: 8 | W7: 8 | X7: 0 | Y7: 0 | Z7: 0 | AA7: 0 | AB7: 50.467017 | AC7: Wie sichern Unternehmen, Hochschulen, Kammern und Arbeitsverwaltung Fachkräfte für Transformation, Pflege, Technik und Verwaltung? | AD7: Arbeitsmarkt, Fachkräfte und Qualifizierung: Handwerkskammern Rheinland-Pfalz (implementation_anchor, 5) + Ministerium für Wirtschaft, Verkehr, Landwirtschaft und Weinbau (profit_anchor, 4). | AE7: Handwerkskammern Rheinland-Pfalz | Ministerium für Wirtschaft, Verkehr, Landwirtschaft und Weinbau | AF7: arbeitsmarkt-fachkraefte-handwerkskammern-rheinland-pfalz-ministerium-für-wirtschaft-verkehr-la
A8: C0007 | B8: x_0007 | C8: 0 | D8: Architektenkammer Rheinland-Pfalz | E8: Aturas GmbH | F8: 3 | G8: 4 | H8: implementation_anchor | I8: construction_planning_anchor | J8: profit_anchor | K8: technology_digital_anchor | L8: technologie | M8: digitale_bau_verwaltung_planung | N8: Digitale Bau-, Planungs- und Genehmigungsprozesse | O8: 5 | P8: 4 | Q8: 13 | R8: 4 | S8: 0 | T8: 0 | U8: 2 | V8: 8 | W8: 8 | X8: 0 | Y8: 0 | Z8: 0 | AA8: 0 | AB8: 37.99019 | AC8: Wie können Bau, Planung, Genehmigung und Verwaltung durch digitale Werkzeuge schneller und rechtssicherer werden? | AD8: Digitale Bau-, Planungs- und Genehmigungsprozesse: Architektenkammer Rheinland-Pfalz (implementation_anchor, 5) + Aturas GmbH (profit_anchor, 4). | AE8: Architektenkammer Rheinland-Pfalz | Aturas GmbH | AF8: digitale-bau-verwaltung-planung-architektenkammer-rheinland-pfalz-aturas-gmbh
A9: C0008 | B9: x_0008 | C9: 0 | D9: Architektenkammer Rheinland-Pfalz | E9: BRICKMAKERS AG | F9: 3 | G9: 12 | H9: implementation_anchor | I9: construction_planning_anchor | J9: profit_anchor | K9: technology_digital_anchor | L9: technologie | M9: digitale_bau_verwaltung_planung | N9: Digitale Bau-, Planungs- und Genehmigungsprozesse | O9: 5 | P9: 4 | Q9: 13 | R9: 4 | S9: 0 | T9: 0 | U9: 2 | V9: 8 | W9: 8 | X9: 0 | Y9: 0 | Z9: 0 | AA9: 0 | AB9: 37.99019 | AC9: Wie können Bau, Planung, Genehmigung und Verwaltung durch digitale Werkzeuge schneller und rechtssicherer werden? | AD9: Digitale Bau-, Planungs- und Genehmigungsprozesse: Architektenkammer Rheinland-Pfalz (implementation_anchor, 5) + BRICKMAKERS AG (profit_anchor, 4). | AE9: Architektenkammer Rheinland-Pfalz | BRICKMAKERS AG | AF9: digitale-bau-verwaltung-planung-architektenkammer-rheinland-pfalz-brickmakers-ag
A10: C0009 | B10: x_0009 | C10: 0 | D10: Architektenkammer Rheinland-Pfalz | E10: Empolis Information Management GmbH | F10: 3 | G10: 23 | H10: implementation_anchor | I10: construction_planning_anchor | J10: profit_anchor | K10: technology_digital_anchor | L10: technologie | M10: digitale_bau_verwaltung_planung | N10: Digitale Bau-, Planungs- und Genehmigungsprozesse | O10: 5 | P10: 4 | Q10: 13 | R10: 4 | S10: 0 | T10: 0 | U10: 2 | V10: 8 | W10: 8 | X10: 0 | Y10: 0 | Z10: 0 | AA10: 0 | AB10: 37.99019 | AC10: Wie können Bau, Planung, Genehmigung und Verwaltung durch digitale Werkzeuge schneller und rechtssicherer werden? | AD10: Digitale Bau-, Planungs- und Genehmigungsprozesse: Architektenkammer Rheinland-Pfalz (implementation_anchor, 5) + Empolis Information Management GmbH (profit_anchor, 4). | AE10: Architektenkammer Rheinland-Pfalz | Empolis Information Management GmbH | AF10: digitale-bau-verwaltung-planung-architektenkammer-rheinland-pfalz-empolis-information-managemen
A11: C0010 | B11: x_0010 | C11: 0 | D11: Architektenkammer Rheinland-Pfalz | E11: Ministerium für Wirtschaft, Verkehr, Landwirtschaft und Weinbau | F11: 3 | G11: 70 | H11: implementation_anchor | I11: construction_planning_anchor | J11: profit_anchor | K11: public_policy_anchor | L11: technologie | M11: digitale_bau_verwaltung_planung | N11: Digitale Bau-, Planungs- und Genehmigungsprozesse | O11: 5 | P11: 4 | Q11: 13 | R11: 4 | S11: 0 | T11: 0 | U11: 2 | V11: 8 | W11: 8 | X11: 0 | Y11: 0 | Z11: 0 | AA11: 0 | AB11: 42.223735 | AC11: Wie können Bau, Planung, Genehmigung und Verwaltung durch digitale Werkzeuge schneller und rechtssicherer werden? | AD11: Digitale Bau-, Planungs- und Genehmigungsprozesse: Architektenkammer Rheinland-Pfalz (implementation_anchor, 5) + Ministerium für Wirtschaft, Verkehr, Landwirtschaft und Weinbau (profit_anchor, 4). | AE11: Architektenkammer Rheinland-Pfalz | Ministerium für Wirtschaft, Verkehr, Landwirtschaft und Weinbau | AF11: digitale-bau-verwaltung-planung-architektenkammer-rheinland-pfalz-ministerium-für-wirtschaft-ve
A12: C0011 | B12: x_0011 | C12: 0 | D12: Aturas GmbH | E12: Ingenieurkammer Rheinland-Pfalz | F12: 4 | G12: 44 | H12: profit_anchor | I12: technology_digital_anchor | J12: implementation_anchor | K12: construction_planning_anchor | L12: technologie | M12: digitale_bau_verwaltung_planung | N12: Digitale Bau-, Planungs- und Genehmigungsprozesse | O12: 4 | P12: 5 | Q12: 13 | R12: 4 | S12: 0 | T12: 0 | U12: 2 | V12: 8 | W12: 8 | X12: 0 | Y12: 0 | Z12: 0 | AA12: 0 | AB12: 37.99019 | AC12: Wie können Bau, Planung, Genehmigung und Verwaltung durch digitale Werkzeuge schneller und rechtssicherer werden? | AD12: Digitale Bau-, Planungs- und Genehmigungsprozesse: Aturas GmbH (profit_anchor, 4) + Ingenieurkammer Rheinland-Pfalz (implementation_anchor, 5). | AE12: Aturas GmbH | Ingenieurkammer Rheinland-Pfalz | AF12: digitale-bau-verwaltung-planung-aturas-gmbh-ingenieurkammer-rheinland-pfalz
A13: C0012 | B13: x_0012 | C13: 0 | D13: BRICKMAKERS AG | E13: Ingenieurkammer Rheinland-Pfalz | F13: 12 | G13: 44 | H13: profit_anchor | I13: technology_digital_anchor | J13: implementation_anchor | K13: construction_planning_anchor | L13: technologie | M13: digitale_bau_verwaltung_planung | N13: Digitale Bau-, Planungs- und Genehmigungsprozesse | O13: 4 | P13: 5 | Q13: 13 | R13: 4 | S13: 0 | T13: 0 | U13: 2 | V13: 8 | W13: 8 | X13: 0 | Y13: 0 | Z13: 0 | AA13: 0 | AB13: 37.99019 | AC13: Wie können Bau, Planung, Genehmigung und Verwaltung durch digitale Werkzeuge schneller und rechtssicherer werden? | AD13: Digitale Bau-, Planungs- und Genehmigungsprozesse: BRICKMAKERS AG (profit_anchor, 4) + Ingenieurkammer Rheinland-Pfalz (implementation_anchor, 5). | AE13: BRICKMAKERS AG | Ingenieurkammer Rheinland-Pfalz | AF13: digitale-bau-verwaltung-planung-brickmakers-ag-ingenieurkammer-rheinland-pfalz
... A695: C0694 | B695: x_0694 | C695: 0 | D695: Evangelische Kirche der Pfalz | E695: ZDF – Zweites Deutsches Fernsehen | F695: 28 | G695: 102 | H695: context_actor | I695: culture_foundation_anchor | J695: context_actor | K695: media_publicity_anchor | L695: kultur | M695: musikstipendium_talentfoerderung | N695: Talentförderung, Musik und Nachwuchs | O695: 3 | P695: 4 | Q695: 11 | R695: 2 | S695: 0 | T695: 0 | U695: 1 | V695: 3 | W695: 4 | X695: 0 | Y695: 0 | Z695: 0 | AA695: 4 | AB695: 24.782714 | AC695: Wie lassen sich kulturelle Talentförderung, Bildung und regionale Sichtbarkeit verbinden? | AD695: Talentförderung, Musik und Nachwuchs: Evangelische Kirche der Pfalz (context_actor, 3) + ZDF – Zweites Deutsches Fernsehen (context_actor, 4). | AE695: Evangelische Kirche der Pfalz | ZDF – Zweites Deutsches Fernsehen | AF695: musikstipendium-talentfoerderung-evangelische-kirche-der-pfalz-zdf-zweites-deutsches-fernsehen

Sheet Member_Constraints
A1: member_id | B1: member_name | C1: actor_role | D1: selected_count | E1: limit | F1: slack | G1: constraint_status
A2: 1 | B2: 1. FSV Mainz 05 e.V. | C2: context_actor | D2: =SUMIFS(Candidate_Patterns!$C:$C,Candidate_Patterns!$F:$F,A2)+SUMIFS(Candidate_Patterns!$C:$C,Candidate_Patterns!$G:$G,A2) | E2: 1 | F2: =E2-D2 | G2: =IF(F2>=0,"OK","VIOLATION")
A3: 2 | B3: AOK Rheinland-Pfalz/Saarland | C3: context_actor | D3: =SUMIFS(Candidate_Patterns!$C:$C,Candidate_Patterns!$F:$F,A3)+SUMIFS(Candidate_Patterns!$C:$C,Candidate_Patterns!$G:$G,A3) | E3: 1 | F3: =E3-D3 | G3: =IF(F3>=0,"OK","VIOLATION")
A4: 3 | B4: Architektenkammer Rheinland-Pfalz | C4: implementation_anchor | D4: =SUMIFS(Candidate_Patterns!$C:$C,Candidate_Patterns!$F:$F,A4)+SUMIFS(Candidate_Patterns!$C:$C,Candidate_Patterns!$G:$G,A4) | E4: 1 | F4: =E4-D4 | G4: =IF(F4>=0,"OK","VIOLATION")
A5: 4 | B5: Aturas GmbH | C5: profit_anchor | D5: =SUMIFS(Candidate_Patterns!$C:$C,Candidate_Patterns!$F:$F,A5)+SUMIFS(Candidate_Patterns!$C:$C,Candidate_Patterns!$G:$G,A5) | E5: 1 | F5: =E5-D5 | G5: =IF(F5>=0,"OK","VIOLATION")
A6: 5 | B6: Barmherzige Brüder Trier gGmbH | C6: context_actor | D6: =SUMIFS(Candidate_Patterns!$C:$C,Candidate_Patterns!$F:$F,A6)+SUMIFS(Candidate_Patterns!$C:$C,Candidate_Patterns!$G:$G,A6) | E6: 1 | F6: =E6-D6 | G6: =IF(F6>=0,"OK","VIOLATION")
A7: 6 | B7: BASF SE | C7: profit_anchor | D7: =SUMIFS(Candidate_Patterns!$C:$C,Candidate_Patterns!$F:$F,A7)+SUMIFS(Candidate_Patterns!$C:$C,Candidate_Patterns!$G:$G,A7) | E7: 1 | F7: =E7-D7 | G7: =IF(F7>=0,"OK","VIOLATION")
A8: 7 | B8: Bauern- und Winzerverband Rheinland-Pfalz Süd e.V. | C8: implementation_anchor | D8: =SUMIFS(Candidate_Patterns!$C:$C,Candidate_Patterns!$F:$F,A8)+SUMIFS(Candidate_Patterns!$C:$C,Candidate_Patterns!$G:$G,A8) | E8: 1 | F8: =E8-D8 | G8: =IF(F8>=0,"OK","VIOLATION")
A9: 8 | B9: Bauwirtschaft Rheinland-Pfalz e.V. | C9: context_actor | D9: =SUMIFS(Candidate_Patterns!$C:$C,Candidate_Patterns!$F:$F,A9)+SUMIFS(Candidate_Patterns!$C:$C,Candidate_Patterns!$G:$G,A9) | E9: 1 | F9: =E9-D9 | G9: =IF(F9>=0,"OK","VIOLATION")
A10: 9 | B10: Bernd Hummel Holding GmbH | C10: profit_anchor | D10: =SUMIFS(Candidate_Patterns!$C:$C,Candidate_Patterns!$F:$F,A10)+SUMIFS(Candidate_Patterns!$C:$C,Candidate_Patterns!$G:$G,A10) | E10: 1 | F10: =E10-D10 | G10: =IF(F10>=0,"OK","VIOLATION")
A11: 10 | B11: Bitburger Braugruppe GmbH | C11: profit_anchor | D11: =SUMIFS(Candidate_Patterns!$C:$C,Candidate_Patterns!$F:$F,A11)+SUMIFS(Candidate_Patterns!$C:$C,Candidate_Patterns!$G:$G,A11) | E11: 1 | F11: =E11-D11 | G11: =IF(F11>=0,"OK","VIOLATION")
A12: 11 | B12: Boehringer Ingelheim Pharma GmbH & Co. KG | C12: profit_anchor | D12: =SUMIFS(Candidate_Patterns!$C:$C,Candidate_Patterns!$F:$F,A12)+SUMIFS(Candidate_Patterns!$C:$C,Candidate_Patterns!$G:$G,A12) | E12: 1 | F12: =E12-D12 | G12: =IF(F12>=0,"OK","VIOLATION")
A13: 12 | B13: BRICKMAKERS AG | C13: profit_anchor | D13: =SUMIFS(Candidate_Patterns!$C:$C,Candidate_Patterns!$F:$F,A13)+SUMIFS(Candidate_Patterns!$C:$C,Candidate_Patterns!$G:$G,A13) | E13: 1 | F13: =E13-D13 | G13: =IF(F13>=0,"OK","VIOLATION")
... A103: 102 | B103: ZDF – Zweites Deutsches Fernsehen | C103: context_actor | D103: =SUMIFS(Candidate_Patterns!$C:$C,Candidate_Patterns!$F:$F,A103)+SUMIFS(Candidate_Patterns!$C:$C,Candidate_Patterns!$G:$G,A103) | E103: 1 | F103: =E103-D103 | G103: =IF(F103>=0,"OK","VIOLATION")

Sheet Cluster_Constraints
A1: concrete_cluster | B1: themenfeld | C1: cluster_label | D1: selected_count | E1: limit | F1: slack | G1: constraint_status
A2: energie_versorgungssicherheit | B2: nachhaltigkeit | C2: Energie, Netze und Versorgungssicherheit | D2: =SUMIFS(Candidate_Patterns!$C:$C,Candidate_Patterns!$K:$K,A2) | E2: 2 | F2: =E2-D2 | G2: =IF(F2>=0,"OK","VIOLATION")
A3: kreislaufwirtschaft_bau_ebv | B3: nachhaltigkeit | C3: Kreislaufwirtschaft, Bau und Ersatzbaustoffverordnung | D3: =SUMIFS(Candidate_Patterns!$C:$C,Candidate_Patterns!$K:$K,A3) | E3: 2 | F3: =E3-D3 | G3: =IF(F3>=0,"OK","VIOLATION")
A4: wasser_umwelttechnik_resilienz | B4: nachhaltigkeit | C4: Wasser, Umwelttechnik und kommunale Resilienz | D4: =SUMIFS(Candidate_Patterns!$C:$C,Candidate_Patterns!$K:$K,A4) | E4: 2 | F4: =E4-D4 | G4: =IF(F4>=0,"OK","VIOLATION")
A5: klima_anpassung_stadt_land | B5: nachhaltigkeit | C5: Klimaanpassung in Stadt und Land | D5: =SUMIFS(Candidate_Patterns!$C:$C,Candidate_Patterns!$K:$K,A5) | E5: 2 | F5: =E5-D5 | G5: =IF(F5>=0,"OK","VIOLATION")
A6: standort_investition_transformation | B6: wirtschaft | C6: Standort, Investition und industrielle Transformation | D6: =SUMIFS(Candidate_Patterns!$C:$C,Candidate_Patterns!$K:$K,A6) | E6: 2 | F6: =E6-D6 | G6: =IF(F6>=0,"OK","VIOLATION")
A7: mittelstand_digitalisierung_produktivitaet | B7: wirtschaft | C7: Mittelstand, Digitalisierung und Produktivität | D7: =SUMIFS(Candidate_Patterns!$C:$C,Candidate_Patterns!$K:$K,A7) | E7: 2 | F7: =E7-D7 | G7: =IF(F7>=0,"OK","VIOLATION")
A8: arbeitsmarkt_fachkraefte | B8: wirtschaft | C8: Arbeitsmarkt, Fachkräfte und Qualifizierung | D8: =SUMIFS(Candidate_Patterns!$C:$C,Candidate_Patterns!$K:$K,A8) | E8: 2 | F8: =E8-D8 | G8: =IF(F8>=0,"OK","VIOLATION")
A9: finanzierung_foerderung_transformation | B9: wirtschaft | C9: Finanzierung und Förderung von Transformation | D9: =SUMIFS(Candidate_Patterns!$C:$C,Candidate_Patterns!$K:$K,A9) | E9: 2 | F9: =E9-D9 | G9: =IF(F9>=0,"OK","VIOLATION")
A10: ki_daten_verwaltung_wirtschaft | B10: technologie | C10: KI, Daten und Verwaltungs-/Wirtschaftsanwendungen | D10: =SUMIFS(Candidate_Patterns!$C:$C,Candidate_Patterns!$K:$K,A10) | E10: 2 | F10: =E10-D10 | G10: =IF(F10>=0,"OK","VIOLATION")
A11: industrie_40_automation | B11: technologie | C11: Industrie 4.0, Automatisierung und Produktion | D11: =SUMIFS(Candidate_Patterns!$C:$C,Candidate_Patterns!$K:$K,A11) | E11: 2 | F11: =E11-D11 | G11: =IF(F11>=0,"OK","VIOLATION")
A12: cyber_resilienz_kritische_infrastruktur | B12: technologie | C12: Cyberresilienz und kritische Infrastruktur | D12: =SUMIFS(Candidate_Patterns!$C:$C,Candidate_Patterns!$K:$K,A12) | E12: 2 | F12: =E12-D12 | G12: =IF(F12>=0,"OK","VIOLATION")
A13: digitale_bau_verwaltung_planung | B13: technologie | C13: Digitale Bau-, Planungs- und Genehmigungsprozesse | D13: =SUMIFS(Candidate_Patterns!$C:$C,Candidate_Patterns!$K:$K,A13) | E13: 2 | F13: =E13-D13 | G13: =IF(F13>=0,"OK","VIOLATION")
... A25: sport_region_identifikation | B25: gesellschaft | C25: Sport, Region und gesellschaftliche Identifikation | D25: =SUMIFS(Candidate_Patterns!$C:$C,Candidate_Patterns!$K:$K,A25) | E25: 2 | F25: =E25-D25 | G25: =IF(F25>=0,"OK","VIOLATION")

Sheet Static_Clusters
A1: concrete_cluster | B1: themenfeld | C1: cluster_label | D1: static_problem_question | E1: signal_keywords | F1: priority_weight
A2: energie_versorgungssicherheit | B2: nachhaltigkeit | C2: Energie, Netze und Versorgungssicherheit | D2: Wie bleiben Unternehmen, Kommunen und Infrastrukturträger in Rheinland-Pfalz investitions- und versorgungssicher? | E2: energiepreise, strompreise, wärme, waerme, netzausbau, versorgungssicherheit, erneuerbare energien, speicher, photovoltaik, wasserstoff, standortkosten, energieintensive industrie | F2: 8.8
A3: kreislaufwirtschaft_bau_ebv | B3: nachhaltigkeit | C3: Kreislaufwirtschaft, Bau und Ersatzbaustoffverordnung | D3: Wie können Bauwirtschaft, Rohstoffindustrie, Kommunen und Verwaltung Kreislaufwirtschaft praktisch und rechtssicher umsetzen? | E3: ersatzbaustoffverordnung, ebv, einbaukarte, recyclingbaustoffe, rohstoffindustrie, bauwirtschaft, kommunen, verwaltung, planungssicherheit, regulierung, genehmigung | F3: 9
A4: wasser_umwelttechnik_resilienz | B4: nachhaltigkeit | C4: Wasser, Umwelttechnik und kommunale Resilienz | D4: Wie können Kommunen und Infrastrukturträger Wasser-, Abwasser- und Umwelttechnik digitaler und resilienter steuern? | E4: wasser, abwasser, umwelttechnik, prozesssteuerung, sensorik, cloud, kommunale infrastruktur, klimafolgen, resilienz, versorgung, entsorgung | F4: 7.7
A5: klima_anpassung_stadt_land | B5: nachhaltigkeit | C5: Klimaanpassung in Stadt und Land | D5: Wie reagieren Kommunen, Bauwirtschaft, Landwirtschaft und Infrastruktur auf Hitze, Starkregen und Flächendruck? | E5: starkregen, hitze, klimaanpassung, flächenverbrauch, flaechenverbrauch, innenstadt, mobilität, mobilitaet, stadtentwicklung, biodiversität, biodiversitaet, landwirtschaft, kommunen | F5: 5
A6: standort_investition_transformation | B6: wirtschaft | C6: Standort, Investition und industrielle Transformation | D6: Welche Standortbedingungen entscheiden darüber, ob Unternehmen in Rheinland-Pfalz investieren, modernisieren oder verlagern? | E6: investition, standort, produktion, werk, kapazität, kapazitaet, arbeitsplätze, arbeitsplaetze, modernisierung, transformation, wettbewerbsfähigkeit, wettbewerbsfaehigkeit, industrie, export, lieferketten | F6: 7.5
A7: mittelstand_digitalisierung_produktivitaet | B7: wirtschaft | C7: Mittelstand, Digitalisierung und Produktivität | D7: Wie können mittelständische Unternehmen digitale Werkzeuge praktisch einsetzen, ohne dass daraus nur Pilotprojekte entstehen? | E7: digitalisierung, mittelstand, produktivität, produktivitaet, automatisierung, ki, software, plattform, prozessoptimierung, industrie 4.0, cloud, erp | F7: 5
A8: arbeitsmarkt_fachkraefte | B8: wirtschaft | C8: Arbeitsmarkt, Fachkräfte und Qualifizierung | D8: Wie sichern Unternehmen, Hochschulen, Kammern und Arbeitsverwaltung Fachkräfte für Transformation, Pflege, Technik und Verwaltung? | E8: fachkräfte, fachkraefte, ausbildung, weiterbildung, qualifizierung, duale ausbildung, arbeitsmarkt, personal, recruiting, integration, zuwanderung, nachwuchs | F8: 8.6
A9: finanzierung_foerderung_transformation | B9: wirtschaft | C9: Finanzierung und Förderung von Transformation | D9: Wie kommen Investitionen, Fördermittel, Banken und Unternehmensstrategien schneller zusammen? | E9: förderung, foerderung, finanzierung, kredit, investition, kapital, transformation, mittelstand, nachfolge, innovation, risiko, bank | F9: 5
A10: ki_daten_verwaltung_wirtschaft | B10: technologie | C10: KI, Daten und Verwaltungs-/Wirtschaftsanwendungen | D10: Wo können KI und Datenplattformen in Unternehmen, Verwaltung und öffentlicher Infrastruktur konkret Nutzen stiften? | E10: ki, künstliche intelligenz, kuenstliche intelligenz, daten, plattform, automatisierung, verwaltung, e-government, prozessdigitalisierung, chatbot, wissensmanagement | F10: 7.9
A11: industrie_40_automation | B11: technologie | C11: Industrie 4.0, Automatisierung und Produktion | D11: Wie wird industrielle Produktion in Rheinland-Pfalz digitaler, robuster und wettbewerbsfähiger? | E11: industrie 4.0, automatisierung, produktion, sensorik, maschinenbau, digitaler zwilling, robotik, prozesssteuerung, fertigung, smart factory | F11: 5
A12: cyber_resilienz_kritische_infrastruktur | B12: technologie | C12: Cyberresilienz und kritische Infrastruktur | D12: Wie schützen Unternehmen, Kommunen und Versorger digitale Systeme, Daten und kritische Infrastruktur? | E12: cybersicherheit, it-sicherheit, resilienz, kritische infrastruktur, krisenmanagement, datenschutz, cloud, netzwerke, kommunen, versorgung | F12: 5
A13: digitale_bau_verwaltung_planung | B13: technologie | C13: Digitale Bau-, Planungs- und Genehmigungsprozesse | D13: Wie können Bau, Planung, Genehmigung und Verwaltung durch digitale Werkzeuge schneller und rechtssicherer werden? | E13: bim, planung, genehmigung, bauverwaltung, einbaukarte, ersatzbaustoffverordnung, kommunen, verwaltung, digitales tool, plattform | F13: 7.4
... A25: sport_region_identifikation | B25: gesellschaft | C25: Sport, Region und gesellschaftliche Identifikation | D25: Wie können Sportvereine als regionale Plattformen für Bildung, Teilhabe, Gesundheit oder Standortbindung wirken? | E25: sport, verein, nachwuchs, bildung, gesundheit, integration, fans, region, identifikation, gesellschaftliches engagement | F25: 5

Sheet Member_Cluster_Matrix
A1: member_id | B1: member_name | C1: actor_role | D1: energie_versorgungssicherheit | E1: kreislaufwirtschaft_bau_ebv | F1: wasser_umwelttechnik_resilienz | G1: klima_anpassung_stadt_land | H1: standort_investition_transformation | I1: mittelstand_digitalisierung_produktivitaet | J1: arbeitsmarkt_fachkraefte | K1: finanzierung_foerderung_transformation | L1: ki_daten_verwaltung_wirtschaft | M1: industrie_40_automation | N1: cyber_resilienz_kritische_infrastruktur | O1: digitale_bau_verwaltung_planung | P1: kultur_standort_identitaet | Q1: kreativwirtschaft_digitale_medien | R1: musikstipendium_talentfoerderung | S1: hochschule_wirtschaft_transfer | T1: weiterbildung_lebenslanges_lernen | U1: wissenschaft_demokratie_gesellschaft | V1: verwaltungswissen_digitalisierung | W1: gesundheit_versorgung_praevention | X1: pflege_fachkraefte_sozialwirtschaft | Y1: teilhabe_inklusion_arbeitsmarkt | Z1: demokratie_medien_zusammenhalt | AA1: sport_region_identifikation
A2: 1 | B2: 1. FSV Mainz 05 e.V. | C2: context_actor | D2: 0 | E2: 0 | F2: 0 | G2: 0 | H2: 0 | I2: 0 | J2: 0 | K2: 0 | L2: 0 | M2: 0 | N2: 0 | O2: 0 | P2: 4 | Q2: 3 | R2: 0 | S2: 0 | T2: 0 | U2: 0 | V2: 0 | W2: 0 | X2: 0 | Y2: 0 | Z2: 3 | AA2: 5
A3: 2 | B3: AOK Rheinland-Pfalz/Saarland | C3: context_actor | D3: 0 | E3: 0 | F3: 0 | G3: 0 | H3: 0 | I3: 0 | J3: 0 | K3: 0 | L3: 0 | M3: 0 | N3: 0 | O3: 0 | P3: 0 | Q3: 0 | R3: 0 | S3: 0 | T3: 0 | U3: 0 | V3: 0 | W3: 5 | X3: 4 | Y3: 0 | Z3: 0 | AA3: 4
A4: 3 | B4: Architektenkammer Rheinland-Pfalz | C4: implementation_anchor | D4: 0 | E4: 4 | F4: 0 | G4: 4 | H4: 0 | I4: 0 | J4: 0 | K4: 0 | L4: 0 | M4: 0 | N4: 0 | O4: 5 | P4: 0 | Q4: 0 | R4: 0 | S4: 0 | T4: 0 | U4: 0 | V4: 0 | W4: 0 | X4: 0 | Y4: 0 | Z4: 0 | AA4: 0
A5: 4 | B5: Aturas GmbH | C5: profit_anchor | D5: 0 | E5: 0 | F5: 0 | G5: 0 | H5: 0 | I5: 4 | J5: 0 | K5: 0 | L5: 4 | M5: 0 | N5: 0 | O5: 4 | P5: 0 | Q5: 0 | R5: 0 | S5: 0 | T5: 0 | U5: 0 | V5: 4 | W5: 0 | X5: 0 | Y5: 0 | Z5: 0 | AA5: 0
A6: 5 | B6: Barmherzige Brüder Trier gGmbH | C6: context_actor | D6: 0 | E6: 0 | F6: 0 | G6: 0 | H6: 0 | I6: 0 | J6: 4 | K6: 0 | L6: 0 | M6: 0 | N6: 0 | O6: 0 | P6: 0 | Q6: 0 | R6: 0 | S6: 0 | T6: 4 | U6: 0 | V6: 0 | W6: 4 | X6: 5 | Y6: 4 | Z6: 0 | AA6: 0
A7: 6 | B7: BASF SE | C7: profit_anchor | D7: 4 | E7: 0 | F7: 0 | G7: 0 | H7: 5 | I7: 0 | J7: 3 | K7: 0 | L7: 0 | M7: 4 | N7: 0 | O7: 0 | P7: 0 | Q7: 0 | R7: 0 | S7: 4 | T7: 0 | U7: 0 | V7: 0 | W7: 0 | X7: 0 | Y7: 0 | Z7: 0 | AA7: 0
A8: 7 | B8: Bauern- und Winzerverband Rheinland-Pfalz Süd e.V. | C8: implementation_anchor | D8: 0 | E8: 0 | F8: 0 | G8: 5 | H8: 0 | I8: 0 | J8: 0 | K8: 0 | L8: 0 | M8: 0 | N8: 0 | O8: 0 | P8: 0 | Q8: 0 | R8: 0 | S8: 0 | T8: 0 | U8: 0 | V8: 0 | W8: 0 | X8: 0 | Y8: 0 | Z8: 0 | AA8: 0
A9: 8 | B9: Bauwirtschaft Rheinland-Pfalz e.V. | C9: context_actor | D9: 0 | E9: 5 | F9: 0 | G9: 4 | H9: 0 | I9: 0 | J9: 0 | K9: 0 | L9: 0 | M9: 0 | N9: 0 | O9: 5 | P9: 0 | Q9: 0 | R9: 0 | S9: 0 | T9: 0 | U9: 0 | V9: 0 | W9: 0 | X9: 0 | Y9: 0 | Z9: 0 | AA9: 0
A10: 9 | B10: Bernd Hummel Holding GmbH | C10: profit_anchor | D10: 0 | E10: 0 | F10: 0 | G10: 0 | H10: 0 | I10: 0 | J10: 0 | K10: 0 | L10: 0 | M10: 0 | N10: 0 | O10: 0 | P10: 0 | Q10: 0 | R10: 0 | S10: 0 | T10: 0 | U10: 0 | V10: 0 | W10: 0 | X10: 0 | Y10: 0 | Z10: 0 | AA10: 0
A11: 10 | B11: Bitburger Braugruppe GmbH | C11: profit_anchor | D11: 0 | E11: 0 | F11: 0 | G11: 0 | H11: 4 | I11: 0 | J11: 0 | K11: 0 | L11: 0 | M11: 0 | N11: 0 | O11: 0 | P11: 0 | Q11: 0 | R11: 0 | S11: 0 | T11: 0 | U11: 0 | V11: 0 | W11: 0 | X11: 0 | Y11: 0 | Z11: 0 | AA11: 0
A12: 11 | B12: Boehringer Ingelheim Pharma GmbH & Co. KG | C12: profit_anchor | D12: 0 | E12: 0 | F12: 0 | G12: 0 | H12: 5 | I12: 0 | J12: 3 | K12: 3 | L12: 0 | M12: 0 | N12: 0 | O12: 0 | P12: 0 | Q12: 0 | R12: 0 | S12: 4 | T12: 0 | U12: 0 | V12: 0 | W12: 4 | X12: 0 | Y12: 0 | Z12: 0 | AA12: 0
A13: 12 | B13: BRICKMAKERS AG | C13: profit_anchor | D13: 0 | E13: 0 | F13: 0 | G13: 0 | H13: 0 | I13: 5 | J13: 0 | K13: 0 | L13: 5 | M13: 0 | N13: 4 | O13: 4 | P13: 0 | Q13: 0 | R13: 0 | S13: 4 | T13: 0 | U13: 0 | V13: 0 | W13: 0 | X13: 0 | Y13: 0 | Z13: 0 | AA13: 0
... A103: 102 | B103: ZDF – Zweites Deutsches Fernsehen | C103: context_actor | D103: 0 | E103: 0 | F103: 0 | G103: 0 | H103: 0 | I103: 0 | J103: 0 | K103: 0 | L103: 0 | M103: 0 | N103: 0 | O103: 0 | P103: 5 | Q103: 5 | R103: 4 | S103: 0 | T103: 0 | U103: 5 | V103: 0 | W103: 0 | X103: 0 | Y103: 0 | Z103: 5 | AA103: 0

Sheet Scoring_Rules
A1: Component | B1: Meaning | C1: Default logic used here | D1: Constraint or objective?
A2: candidate universe P | B2: Rows in Candidate_Patterns; generated from updated member table and 24 static clusters. | C2: For each cluster, include member pairs where both relevance scores are >= 3; rank by score; keep top 30 per cluster. | D2: Candidate generation before SCIP
A3: shared_concrete_clusters | B3: Both actors are relevant to the same concrete cluster. | C3: MIN(14, 4 + relevance_a + relevance_b). | D3: Objective coefficient
A4: complementary_topic_pairs | B4: Useful bridge between actor types/themes. | C4: 4 if roles differ; 1 if both academic_support; 2 if same non-academic role. | D4: Objective coefficient
A5: momentum_from_event_count | B5: Optional live signal momentum from crawler. | C5: Static default 0; later enriched by crawler events. | D5: Objective coefficient
A6: avg_decision_quality | B6: Optional live quality from crawler. | C6: Static default 0; later enriched by signal judge / evidence quality. | D6: Objective coefficient
A7: section_diversity | B7: Different evidence/role logic in one card. | C7: 2 if roles differ; else 1. | D7: Objective coefficient
A8: role_complementarity | B8: Quality of actor bridge. | C8: profit+implementation=8; academic+implementation=7; academic+profit=6; context+profit/implementation=6; context+academic=5; academic+academic=2. | D8: Objective coefficient
A9: application_capability_bridge | B9: Can this pair move from topic to action? | C9: Same role bridge logic: implementation/resource + knowledge/problem owner scores higher. | D9: Objective coefficient
A10: broad_media_penalty | B10: Prevents media over-selection outside public-role lanes. | C10: 0 in this static file; reserved for later media-role refinements. | D10: Objective penalty
A11: weak_profile_penalty | B11: Penalizes weak cluster relevance. | C11: 4 if either actor has relevance < 3; normally 0 because candidates require >= 3. | D11: Objective penalty
A12: academic_only_penalty | B12: Penalizes all-academic cards. | C12: 12 if both actors are academic_support. This keeps universities as support unless the pair is very strong. | D12: Objective penalty
... A14: final_support_score | B14: Support score attached to x_p. | C14: SUM positive components O:U minus penalties V:Y. | D14: Objective coefficient

Sheet Model_Readme
A1: Topic | B1: Explanation
A2: Update performed | B2: Removed Alexianer GmbH from the member universe and all candidate/constraint/matrix sheets. Added Hochschule für Musik Mainz and Hochschule für Gesellschaftsgestaltung (HfGG) with static cluster profiles.
A3: Hochschule für Musik Mainz mapping | B3: academic_support; culture/knowledge profile. Main cluster: Talentförderung, Musik und Nachwuchs (5), plus Kultur/Standortidentität, Kreativwirtschaft, Wissenschaft/Demokratie, Weiterbildung.
A4: HfGG mapping | B4: academic_support; society/sustainability/knowledge profile. Main cluster: Wissenschaft, Demokratie und gesellschaftlicher Zusammenhalt (5), plus Demokratie/Medien/Zusammenhalt, Teilhabe/Inklusion, Klimaanpassung, Hochschule-Wirtschaft-Transfer, Weiterbildung.
A5: Plausible candidate patterns | B5: For every concrete cluster, members with relevance >=3 are eligible. The script creates all pair combinations inside that cluster, scores them, ranks them, and keeps the top 30 cards per cluster. This yields an auditable static candidate universe P.
A6: Scoring decisions | B6: Positive components: shared cluster relevance, role difference/complementarity, section diversity, action bridge, future live signal fields. Negative components: weak profile, academic-only, abstract overlap, media penalty placeholder.
A7: SCIP formulation | B7: Binary weighted set-packing: choose x_p in {0,1} to maximize SUM(final_support_score_p*x_p), subject to max selected cards, member limits, cluster limits, and opportunity duplicate limits.
A8: Dynamic update note | B8: Crawler and feedback should later enrich scores, not rewrite the static member universe or constraints automatically.

Sheet InfoBox_Keyword_Radar
A1: member_id | B1: member_name | C1: homepage | D1: actor_role | E1: actor_subrole | F1: searchable_profile_text | G1: keyword_families_hit | H1: keywords_hit | I1: keyword_hit_count | J1: strongest_static_signal | K1: SOR_interpretation | L1: suggested_use | M1: source_url | N1: extraction_note
A2: 1 | B2: 1. FSV Mainz 05 e.V. | C2: https://www.mainz05.de | D2: context_actor | E2: sports_regional_identity_anchor | F2: 1. FSV Mainz 05 e.V. | context_actor | gesellschaft, kultur | Sport, Region und gesellschaftliche Identifikation (5); Kultur, Standortidentität und regionale Attraktivität (4); Demokratie, Medien und gesellschaftlicher Zusammenhalt (3); Kreativwirtschaft, Medien und digitale Öffentlichkeit (3) | G2: KI / Digital; Wirtschaft / Mittelstand / Standort; Dialog / Netzwerk / Verantwortung; Kultur / Medien / Öffentlichkeit | H2: digital; IT; Wirtschaft; Standort; gesellschaftlich; Zusammenhalt; Kultur; Medien; Öffentlichkeit; Kreativwirtschaft; Standortidentität; Region; gesellschaftliche Identifikation; Demokratie | I2: 14 | J2: Sport, Region und gesellschaftliche Identifikation (5) | K2: Static profile activates 4 keyword family/families: KI / Digital, Wirtschaft / Mittelstand / Standort, Dialog / Netzwerk / Verantwortung, Kultur / Medien / Öffentlichkeit. | L2: Use as convening/context partner for digitalization / data / technology opportunity anchor. | M2: https://www.zirp.de/die-zirp/mitglieder/ | N2: Keyword search over existing static ZIRP member fields in this workbook, designed to mirror/search official ZIRP profile info boxes.
A3: 2 | B3: AOK Rheinland-Pfalz/Saarland | C3: https://www.aok.de/rheinland-pfalz | D3: context_actor | E3: health_social_anchor | F3: AOK Rheinland-Pfalz/Saarland | context_actor | gesellschaft | Gesundheitsversorgung und Prävention (5); Pflege, Fachkräfte und Sozialwirtschaft (4); Sport, Region und gesellschaftliche Identifikation (4) | G3: KI / Digital; Nachhaltigkeit / Klima / Energie; Gesundheit / Pflege / Sozialwirtschaft; Fachkräfte / Arbeit / Qualifizierung; Wirtschaft / Mittelstand / Standort; Dialog / Netzwerk / Verantwortung; Kultur / Medien / Öffentlichkeit | H3: IT; Land; Gesundheit; Gesundheitsversorgung; Pflege; Sozialwirtschaft; Prävention; Versorgung; Fachkräfte; Wirtschaft; gesellschaftlich; Region; gesellschaftliche Identifikation | I3: 13 | J3: Gesundheitsversorgung und Prävention (5) | K3: Static profile activates 7 keyword family/families: KI / Digital, Nachhaltigkeit / Klima / Energie, Gesundheit / Pflege / Sozialwirtschaft, Fachkräfte / Arbeit / Qualifizierung, Wirtschaft / Mittelstand / Standort, Dialog / Netzwerk / Verantwortung, Kultur / Medien / Öffentlichkeit. | L3: Use as convening/context partner for health/social-sector opportunity anchor. | M3: https://www.zirp.de/die-zirp/mitglieder/ | N3: Keyword search over existing static ZIRP member fields in this workbook, designed to mirror/search official ZIRP profile info boxes.
A4: 3 | B4: Architektenkammer Rheinland-Pfalz | C4: https://www.diearchitekten.org | D4: implementation_anchor | E4: construction_planning_anchor | F4: Architektenkammer Rheinland-Pfalz | implementation_anchor | nachhaltigkeit, technologie | Digitale Bau-, Planungs- und Genehmigungsprozesse (5); Klimaanpassung in Stadt und Land (4); Kreislaufwirtschaft, Bau und Ersatzbaustoffverordnung (4) | G4: KI / Digital; Nachhaltigkeit / Klima / Energie; Bau / Raum / Infrastruktur; Wirtschaft / Mittelstand / Standort | H4: digital; IT; Technologie; Nachhaltigkeit; nachhaltig; Klima; Klimaanpassung; Kreislauf; Ersatzbaustoff; Land; Stadt; Bau; Planung; Genehmigung; Wirtschaft | I4: 15 | J4: Digitale Bau-, Planungs- und Genehmigungsprozesse (5) | K4: Static profile activates 4 keyword family/families: KI / Digital, Nachhaltigkeit / Klima / Energie, Bau / Raum / Infrastruktur, Wirtschaft / Mittelstand / Standort. | L4: Use as institutional implementation partner for digitalization / data / technology opportunity anchor. | M4: https://www.zirp.de/die-zirp/mitglieder/ | N4: Keyword search over existing static ZIRP member fields in this workbook, designed to mirror/search official ZIRP profile info boxes.
A5: 4 | B5: Aturas GmbH | C5: https://aturas.com | D5: profit_anchor | E5: technology_digital_anchor | F5: Aturas GmbH | profit_anchor | technologie, wirtschaft, wissen | Digitale Bau-, Planungs- und Genehmigungsprozesse (4); KI, Daten und Verwaltungs-/Wirtschaftsanwendungen (4); Mittelstand, Digitalisierung und Produktivität (4); Verwaltungswissen und digitale Umsetzung (4) | G5: KI / Digital; Innovation / Transfer; Fachkräfte / Arbeit / Qualifizierung; Bau / Raum / Infrastruktur; Wirtschaft / Mittelstand / Standort; Wissenschaft / Bildung / Hochschule | H5: KI; Digitalisierung; digital; Daten; IT; Technologie; Verwaltung; Wissen; Produktivität; Bau; Planung; Genehmigung; Wirtschaft; Mittelstand | I5: 14 | J5: Digitale Bau-, Planungs- und Genehmigungsprozesse (4) | K5: Static profile activates 6 keyword family/families: KI / Digital, Innovation / Transfer, Fachkräfte / Arbeit / Qualifizierung, Bau / Raum / Infrastruktur, Wirtschaft / Mittelstand / Standort, Wissenschaft / Bildung / Hochschule. | L5: Use as implementation/commercial partner for digitalization / data / technology opportunity anchor. | M5: https://www.zirp.de/die-zirp/mitglieder/ | N5: Keyword search over existing static ZIRP member fields in this workbook, designed to mirror/search official ZIRP profile info boxes.
A6: 5 | B6: Barmherzige Brüder Trier gGmbH | C6: https://www.bbtgruppe.de | D6: context_actor | E6: health_social_anchor | F6: Barmherzige Brüder Trier gGmbH | context_actor | gesellschaft, wirtschaft, wissen | Pflege, Fachkräfte und Sozialwirtschaft (5); Arbeitsmarkt, Fachkräfte und Qualifizierung (4); Gesundheitsversorgung und Prävention (4); Teilhabe, Inklusion und Arbeitsmarkt (4); Weiterbildung und lebenslanges Lernen (4) | G6: KI / Digital; Innovation / Transfer; Gesundheit / Pflege / Sozialwirtschaft; Fachkräfte / Arbeit / Qualifizierung; Wirtschaft / Mittelstand / Standort; Wissenschaft / Bildung / Hochschule | H6: IT; Wissen; Gesundheit; Gesundheitsversorgung; Pflege; Sozialwirtschaft; Prävention; Versorgung; Teilhabe; Fachkräfte; Qualifizierung; Weiterbildung; Arbeitsmarkt; lebenslanges Lernen; Wirtschaft; Bildung | I6: 16 | J6: Pflege, Fachkräfte und Sozialwirtschaft (5) | K6: Static profile activates 6 keyword family/families: KI / Digital, Innovation / Transfer, Gesundheit / Pflege / Sozialwirtschaft, Fachkräfte / Arbeit / Qualifizierung, Wirtschaft / Mittelstand / Standort, Wissenschaft / Bildung / Hochschule. | L6: Use as convening/context partner for health/social-sector opportunity anchor. | M6: https://www.zirp.de/die-zirp/mitglieder/ | N6: Keyword search over existing static ZIRP member fields in this workbook, designed to mirror/search official ZIRP profile info boxes.
A7: 6 | B7: BASF SE | C7: https://www.basf.com | D7: profit_anchor | E7: industry_anchor | F7: BASF SE | profit_anchor | nachhaltigkeit, technologie, wirtschaft, wissen | Standort, Investition und industrielle Transformation (5); Energie, Netze und Versorgungssicherheit (4); Hochschule-Wirtschaft-Transfer (4); Industrie 4.0, Automatisierung und Produktion (4); Arbeitsmarkt, Fachkräfte und Qualifizierung (3) | G7: KI / Digital; Innovation / Transfer; Nachhaltigkeit / Klima / Energie; Gesundheit / Pflege / Sozialwirtschaft; Fachkräfte / Arbeit / Qualifizierung; Wirtschaft / Mittelstand / Standort; Wissenschaft / Bildung / Hochschule | H7: IT; Technologie; Automatisierung; Industrie 4.0; Transfer; Wissen; Nachhaltigkeit; nachhaltig; Energie; Netze; Versorgungssicherheit; Versorgung; Fachkräfte; Qualifizierung; Arbeitsmarkt; Wirtschaft; Standort; Industrie; Investition; Transformation; Hochschule | I7: 21 | J7: Standort, Investition und industrielle Transformation (5) | K7: Static profile activates 7 keyword family/families: KI / Digital, Innovation / Transfer, Nachhaltigkeit / Klima / Energie, Gesundheit / Pflege / Sozialwirtschaft, Fachkräfte / Arbeit / Qualifizierung, Wirtschaft / Mittelstand / Standort, Wissenschaft / Bildung / Hochschule. | L7: Use as implementation/commercial partner for health/social-sector opportunity anchor. | M7: https://www.zirp.de/die-zirp/mitglieder/ | N7: Keyword search over existing static ZIRP member fields in this workbook, designed to mirror/search official ZIRP profile info boxes.
A8: 7 | B8: Bauern- und Winzerverband Rheinland-Pfalz Süd e.V. | C8: https://www.bwv-rlp.de | D8: implementation_anchor | E8: agriculture_wine_anchor | F8: Bauern- und Winzerverband Rheinland-Pfalz Süd e.V. | implementation_anchor | nachhaltigkeit | Klimaanpassung in Stadt und Land (5) | G8: KI / Digital; Nachhaltigkeit / Klima / Energie; Bau / Raum / Infrastruktur | H8: IT; Nachhaltigkeit; nachhaltig; Klima; Klimaanpassung; Land; Stadt; Bau | I8: 8 | J8: Klimaanpassung in Stadt und Land (5) | K8: Static profile activates 3 keyword family/families: KI / Digital, Nachhaltigkeit / Klima / Energie, Bau / Raum / Infrastruktur. | L8: Use as institutional implementation partner for digitalization / data / technology opportunity anchor. | M8: https://www.zirp.de/die-zirp/mitglieder/ | N8: Keyword search over existing static ZIRP member fields in this workbook, designed to mirror/search official ZIRP profile info boxes.
